[2022-02-01 17:00:05,716] {taskinstance.py:1032} INFO - Dependencies all met for <TaskInstance: my_dag.choose_best_model manual__2022-02-01T17:00:02.836767+00:00 [queued]>
[2022-02-01 17:00:05,728] {taskinstance.py:1032} INFO - Dependencies all met for <TaskInstance: my_dag.choose_best_model manual__2022-02-01T17:00:02.836767+00:00 [queued]>
[2022-02-01 17:00:05,728] {taskinstance.py:1238} INFO - 
--------------------------------------------------------------------------------
[2022-02-01 17:00:05,729] {taskinstance.py:1239} INFO - Starting attempt 1 of 1
[2022-02-01 17:00:05,729] {taskinstance.py:1240} INFO - 
--------------------------------------------------------------------------------
[2022-02-01 17:00:05,741] {taskinstance.py:1259} INFO - Executing <Task(BranchPythonOperator): choose_best_model> on 2022-02-01 17:00:02.836767+00:00
[2022-02-01 17:00:05,745] {standard_task_runner.py:52} INFO - Started process 108 to run task
[2022-02-01 17:00:05,749] {standard_task_runner.py:76} INFO - Running: ['***', 'tasks', 'run', 'my_dag', 'choose_best_model', 'manual__2022-02-01T17:00:02.836767+00:00', '--job-id', '14', '--raw', '--subdir', 'DAGS_FOLDER/my_dag.py', '--cfg-path', '/tmp/tmp314vrr_p', '--error-file', '/tmp/tmpkzgq9lyn']
[2022-02-01 17:00:05,749] {standard_task_runner.py:77} INFO - Job 14: Subtask choose_best_model
[2022-02-01 17:00:05,798] {logging_mixin.py:109} INFO - Running <TaskInstance: my_dag.choose_best_model manual__2022-02-01T17:00:02.836767+00:00 [running]> on host 1f177efe7f75
[2022-02-01 17:00:05,847] {taskinstance.py:1426} INFO - Exporting the following env vars:
AIRFLOW_CTX_DAG_OWNER=***
AIRFLOW_CTX_DAG_ID=my_dag
AIRFLOW_CTX_TASK_ID=choose_best_model
AIRFLOW_CTX_EXECUTION_DATE=2022-02-01T17:00:02.836767+00:00
AIRFLOW_CTX_DAG_RUN_ID=manual__2022-02-01T17:00:02.836767+00:00
[2022-02-01 17:00:05,855] {python.py:175} INFO - Done. Returned value was: inacurate
[2022-02-01 17:00:05,866] {taskinstance.py:1700} ERROR - Task failed with exception
Traceback (most recent call last):
  File "/home/airflow/.local/lib/python3.7/site-packages/airflow/models/taskinstance.py", line 1329, in _run_raw_task
    self._execute_task_with_callbacks(context)
  File "/home/airflow/.local/lib/python3.7/site-packages/airflow/models/taskinstance.py", line 1455, in _execute_task_with_callbacks
    result = self._execute_task(context, self.task)
  File "/home/airflow/.local/lib/python3.7/site-packages/airflow/models/taskinstance.py", line 1511, in _execute_task
    result = execute_callable(context=context)
  File "/home/airflow/.local/lib/python3.7/site-packages/airflow/operators/python.py", line 215, in execute
    f"Branch callable must return valid task_ids. Invalid tasks found: {invalid_task_ids}"
airflow.exceptions.AirflowException: Branch callable must return valid task_ids. Invalid tasks found: {'inacurate'}
[2022-02-01 17:00:05,874] {taskinstance.py:1277} INFO - Marking task as FAILED. dag_id=my_dag, task_id=choose_best_model, execution_date=20220201T170002, start_date=20220201T170005, end_date=20220201T170005
[2022-02-01 17:00:05,889] {standard_task_runner.py:92} ERROR - Failed to execute job 14 for task choose_best_model
Traceback (most recent call last):
  File "/home/airflow/.local/lib/python3.7/site-packages/airflow/task/task_runner/standard_task_runner.py", line 85, in _start_by_fork
    args.func(args, dag=self.dag)
  File "/home/airflow/.local/lib/python3.7/site-packages/airflow/cli/cli_parser.py", line 48, in command
    return func(*args, **kwargs)
  File "/home/airflow/.local/lib/python3.7/site-packages/airflow/utils/cli.py", line 92, in wrapper
    return f(*args, **kwargs)
  File "/home/airflow/.local/lib/python3.7/site-packages/airflow/cli/commands/task_command.py", line 298, in task_run
    _run_task_by_selected_method(args, dag, ti)
  File "/home/airflow/.local/lib/python3.7/site-packages/airflow/cli/commands/task_command.py", line 107, in _run_task_by_selected_method
    _run_raw_task(args, ti)
  File "/home/airflow/.local/lib/python3.7/site-packages/airflow/cli/commands/task_command.py", line 184, in _run_raw_task
    error_file=args.error_file,
  File "/home/airflow/.local/lib/python3.7/site-packages/airflow/utils/session.py", line 70, in wrapper
    return func(*args, session=session, **kwargs)
  File "/home/airflow/.local/lib/python3.7/site-packages/airflow/models/taskinstance.py", line 1329, in _run_raw_task
    self._execute_task_with_callbacks(context)
  File "/home/airflow/.local/lib/python3.7/site-packages/airflow/models/taskinstance.py", line 1455, in _execute_task_with_callbacks
    result = self._execute_task(context, self.task)
  File "/home/airflow/.local/lib/python3.7/site-packages/airflow/models/taskinstance.py", line 1511, in _execute_task
    result = execute_callable(context=context)
  File "/home/airflow/.local/lib/python3.7/site-packages/airflow/operators/python.py", line 215, in execute
    f"Branch callable must return valid task_ids. Invalid tasks found: {invalid_task_ids}"
airflow.exceptions.AirflowException: Branch callable must return valid task_ids. Invalid tasks found: {'inacurate'}
[2022-02-01 17:00:05,920] {local_task_job.py:154} INFO - Task exited with return code 1
[2022-02-01 17:00:05,979] {local_task_job.py:264} INFO - 0 downstream tasks scheduled from follow-on schedule check
